{
 "cells": [
  {
   "cell_type": "code",
   "execution_count": 5,
   "metadata": {},
   "outputs": [
    {
     "name": "stdout",
     "output_type": "stream",
     "text": [
      "\u001b[33mWARNING: Value for scheme.headers does not match. Please report this to <https://github.com/pypa/pip/issues/9617>\n",
      "distutils: /opt/conda/include/python3.6m/UNKNOWN\n",
      "sysconfig: /opt/conda/include/python3.6m\u001b[0m\n",
      "\u001b[33mWARNING: Additional context:\n",
      "user = False\n",
      "home = None\n",
      "root = None\n",
      "prefix = None\u001b[0m\n",
      "Requirement already satisfied: transformers in /opt/conda/lib/python3.6/site-packages (4.10.0)\n",
      "Requirement already satisfied: packaging in /opt/conda/lib/python3.6/site-packages (from transformers) (20.9)\n",
      "Requirement already satisfied: pyyaml>=5.1 in /opt/conda/lib/python3.6/site-packages (from transformers) (5.4.1)\n",
      "Requirement already satisfied: requests in /opt/conda/lib/python3.6/site-packages (from transformers) (2.25.1)\n",
      "Requirement already satisfied: filelock in /opt/conda/lib/python3.6/site-packages (from transformers) (3.0.12)\n",
      "Requirement already satisfied: huggingface-hub>=0.0.12 in /opt/conda/lib/python3.6/site-packages (from transformers) (0.0.16)\n",
      "Requirement already satisfied: tqdm>=4.27 in /opt/conda/lib/python3.6/site-packages (from transformers) (4.49.0)\n",
      "Requirement already satisfied: dataclasses in /opt/conda/lib/python3.6/site-packages (from transformers) (0.8)\n",
      "Requirement already satisfied: sacremoses in /opt/conda/lib/python3.6/site-packages (from transformers) (0.0.45)\n",
      "Requirement already satisfied: importlib-metadata in /opt/conda/lib/python3.6/site-packages (from transformers) (4.0.1)\n",
      "Requirement already satisfied: numpy>=1.17 in /opt/conda/lib/python3.6/site-packages (from transformers) (1.19.1)\n",
      "Requirement already satisfied: tokenizers<0.11,>=0.10.1 in /opt/conda/lib/python3.6/site-packages (from transformers) (0.10.3)\n",
      "Requirement already satisfied: regex!=2019.12.17 in /opt/conda/lib/python3.6/site-packages (from transformers) (2021.8.28)\n",
      "Requirement already satisfied: typing-extensions in /opt/conda/lib/python3.6/site-packages (from huggingface-hub>=0.0.12->transformers) (3.7.4.3)\n",
      "Requirement already satisfied: pyparsing>=2.0.2 in /opt/conda/lib/python3.6/site-packages (from packaging->transformers) (2.4.7)\n",
      "Requirement already satisfied: zipp>=0.5 in /opt/conda/lib/python3.6/site-packages (from importlib-metadata->transformers) (3.4.1)\n",
      "Requirement already satisfied: urllib3<1.27,>=1.21.1 in /opt/conda/lib/python3.6/site-packages (from requests->transformers) (1.25.11)\n",
      "Requirement already satisfied: idna<3,>=2.5 in /opt/conda/lib/python3.6/site-packages (from requests->transformers) (2.10)\n",
      "Requirement already satisfied: chardet<5,>=3.0.2 in /opt/conda/lib/python3.6/site-packages (from requests->transformers) (3.0.4)\n",
      "Requirement already satisfied: certifi>=2017.4.17 in /opt/conda/lib/python3.6/site-packages (from requests->transformers) (2020.12.5)\n",
      "Requirement already satisfied: click in /opt/conda/lib/python3.6/site-packages (from sacremoses->transformers) (7.1.2)\n",
      "Requirement already satisfied: six in /opt/conda/lib/python3.6/site-packages (from sacremoses->transformers) (1.15.0)\n",
      "Requirement already satisfied: joblib in /opt/conda/lib/python3.6/site-packages (from sacremoses->transformers) (1.0.1)\n",
      "\u001b[33mWARNING: Value for scheme.headers does not match. Please report this to <https://github.com/pypa/pip/issues/9617>\n",
      "distutils: /opt/conda/include/python3.6m/UNKNOWN\n",
      "sysconfig: /opt/conda/include/python3.6m\u001b[0m\n",
      "\u001b[33mWARNING: Additional context:\n",
      "user = False\n",
      "home = None\n",
      "root = None\n",
      "prefix = None\u001b[0m\n",
      "\u001b[33mWARNING: Running pip as root will break packages and permissions. You should install packages reliably by using venv: https://pip.pypa.io/warnings/venv\u001b[0m\n",
      "Note: you may need to restart the kernel to use updated packages.\n",
      "\u001b[33mWARNING: Value for scheme.headers does not match. Please report this to <https://github.com/pypa/pip/issues/9617>\n",
      "distutils: /opt/conda/include/python3.6m/UNKNOWN\n",
      "sysconfig: /opt/conda/include/python3.6m\u001b[0m\n",
      "\u001b[33mWARNING: Additional context:\n",
      "user = False\n",
      "home = None\n",
      "root = None\n",
      "prefix = None\u001b[0m\n",
      "Requirement already satisfied: seaborn in /opt/conda/lib/python3.6/site-packages (0.11.2)\n",
      "Requirement already satisfied: pandas>=0.23 in /opt/conda/lib/python3.6/site-packages (from seaborn) (1.1.5)\n",
      "Requirement already satisfied: numpy>=1.15 in /opt/conda/lib/python3.6/site-packages (from seaborn) (1.19.1)\n",
      "Requirement already satisfied: matplotlib>=2.2 in /opt/conda/lib/python3.6/site-packages (from seaborn) (3.3.4)\n",
      "Requirement already satisfied: scipy>=1.0 in /opt/conda/lib/python3.6/site-packages (from seaborn) (1.2.2)\n",
      "Requirement already satisfied: pyparsing!=2.0.4,!=2.1.2,!=2.1.6,>=2.0.3 in /opt/conda/lib/python3.6/site-packages (from matplotlib>=2.2->seaborn) (2.4.7)\n",
      "Requirement already satisfied: cycler>=0.10 in /opt/conda/lib/python3.6/site-packages (from matplotlib>=2.2->seaborn) (0.10.0)\n",
      "Requirement already satisfied: kiwisolver>=1.0.1 in /opt/conda/lib/python3.6/site-packages (from matplotlib>=2.2->seaborn) (1.3.1)\n",
      "Requirement already satisfied: pillow>=6.2.0 in /opt/conda/lib/python3.6/site-packages (from matplotlib>=2.2->seaborn) (8.2.0)\n",
      "Requirement already satisfied: python-dateutil>=2.1 in /opt/conda/lib/python3.6/site-packages (from matplotlib>=2.2->seaborn) (2.8.1)\n",
      "Requirement already satisfied: six in /opt/conda/lib/python3.6/site-packages (from cycler>=0.10->matplotlib>=2.2->seaborn) (1.15.0)\n",
      "Requirement already satisfied: pytz>=2017.2 in /opt/conda/lib/python3.6/site-packages (from pandas>=0.23->seaborn) (2021.1)\n",
      "\u001b[33mWARNING: Value for scheme.headers does not match. Please report this to <https://github.com/pypa/pip/issues/9617>\n",
      "distutils: /opt/conda/include/python3.6m/UNKNOWN\n",
      "sysconfig: /opt/conda/include/python3.6m\u001b[0m\n",
      "\u001b[33mWARNING: Additional context:\n",
      "user = False\n",
      "home = None\n",
      "root = None\n",
      "prefix = None\u001b[0m\n",
      "\u001b[33mWARNING: Running pip as root will break packages and permissions. You should install packages reliably by using venv: https://pip.pypa.io/warnings/venv\u001b[0m\n",
      "Note: you may need to restart the kernel to use updated packages.\n",
      "\u001b[33mWARNING: Value for scheme.headers does not match. Please report this to <https://github.com/pypa/pip/issues/9617>\n",
      "distutils: /opt/conda/include/python3.6m/UNKNOWN\n",
      "sysconfig: /opt/conda/include/python3.6m\u001b[0m\n",
      "\u001b[33mWARNING: Additional context:\n",
      "user = False\n",
      "home = None\n",
      "root = None\n",
      "prefix = None\u001b[0m\n",
      "Requirement already satisfied: datasets==1.6.2 in /opt/conda/lib/python3.6/site-packages (1.6.2)\n",
      "Requirement already satisfied: requests>=2.19.0 in /opt/conda/lib/python3.6/site-packages (from datasets==1.6.2) (2.25.1)\n",
      "Requirement already satisfied: xxhash in /opt/conda/lib/python3.6/site-packages (from datasets==1.6.2) (2.0.2)\n",
      "Requirement already satisfied: multiprocess in /opt/conda/lib/python3.6/site-packages (from datasets==1.6.2) (0.70.11.1)\n",
      "Requirement already satisfied: tqdm<4.50.0,>=4.27 in /opt/conda/lib/python3.6/site-packages (from datasets==1.6.2) (4.49.0)\n",
      "Requirement already satisfied: pandas in /opt/conda/lib/python3.6/site-packages (from datasets==1.6.2) (1.1.5)\n",
      "Requirement already satisfied: dill in /opt/conda/lib/python3.6/site-packages (from datasets==1.6.2) (0.3.3)\n",
      "Requirement already satisfied: huggingface-hub<0.1.0 in /opt/conda/lib/python3.6/site-packages (from datasets==1.6.2) (0.0.16)\n",
      "Requirement already satisfied: dataclasses in /opt/conda/lib/python3.6/site-packages (from datasets==1.6.2) (0.8)\n",
      "Requirement already satisfied: packaging in /opt/conda/lib/python3.6/site-packages (from datasets==1.6.2) (20.9)\n",
      "Requirement already satisfied: numpy>=1.17 in /opt/conda/lib/python3.6/site-packages (from datasets==1.6.2) (1.19.1)\n",
      "Requirement already satisfied: pyarrow>=1.0.0<4.0.0 in /opt/conda/lib/python3.6/site-packages (from datasets==1.6.2) (4.0.0)\n",
      "Requirement already satisfied: fsspec in /opt/conda/lib/python3.6/site-packages (from datasets==1.6.2) (2021.4.0)\n",
      "Requirement already satisfied: importlib-metadata in /opt/conda/lib/python3.6/site-packages (from datasets==1.6.2) (4.0.1)\n",
      "Requirement already satisfied: filelock in /opt/conda/lib/python3.6/site-packages (from huggingface-hub<0.1.0->datasets==1.6.2) (3.0.12)\n",
      "Requirement already satisfied: typing-extensions in /opt/conda/lib/python3.6/site-packages (from huggingface-hub<0.1.0->datasets==1.6.2) (3.7.4.3)\n",
      "Requirement already satisfied: pyparsing>=2.0.2 in /opt/conda/lib/python3.6/site-packages (from packaging->datasets==1.6.2) (2.4.7)\n",
      "Requirement already satisfied: certifi>=2017.4.17 in /opt/conda/lib/python3.6/site-packages (from requests>=2.19.0->datasets==1.6.2) (2020.12.5)\n",
      "Requirement already satisfied: urllib3<1.27,>=1.21.1 in /opt/conda/lib/python3.6/site-packages (from requests>=2.19.0->datasets==1.6.2) (1.25.11)\n",
      "Requirement already satisfied: chardet<5,>=3.0.2 in /opt/conda/lib/python3.6/site-packages (from requests>=2.19.0->datasets==1.6.2) (3.0.4)\n",
      "Requirement already satisfied: idna<3,>=2.5 in /opt/conda/lib/python3.6/site-packages (from requests>=2.19.0->datasets==1.6.2) (2.10)\n",
      "Requirement already satisfied: zipp>=0.5 in /opt/conda/lib/python3.6/site-packages (from importlib-metadata->datasets==1.6.2) (3.4.1)\n",
      "Requirement already satisfied: python-dateutil>=2.7.3 in /opt/conda/lib/python3.6/site-packages (from pandas->datasets==1.6.2) (2.8.1)\n",
      "Requirement already satisfied: pytz>=2017.2 in /opt/conda/lib/python3.6/site-packages (from pandas->datasets==1.6.2) (2021.1)\n",
      "Requirement already satisfied: six>=1.5 in /opt/conda/lib/python3.6/site-packages (from python-dateutil>=2.7.3->pandas->datasets==1.6.2) (1.15.0)\n",
      "\u001b[33mWARNING: Value for scheme.headers does not match. Please report this to <https://github.com/pypa/pip/issues/9617>\n",
      "distutils: /opt/conda/include/python3.6m/UNKNOWN\n",
      "sysconfig: /opt/conda/include/python3.6m\u001b[0m\n",
      "\u001b[33mWARNING: Additional context:\n",
      "user = False\n",
      "home = None\n",
      "root = None\n",
      "prefix = None\u001b[0m\n",
      "\u001b[33mWARNING: Running pip as root will break packages and permissions. You should install packages reliably by using venv: https://pip.pypa.io/warnings/venv\u001b[0m\n",
      "Note: you may need to restart the kernel to use updated packages.\n"
     ]
    }
   ],
   "source": [
    "%pip install transformers\n",
    "%pip install seaborn\n",
    "%pip install \"datasets==1.6.2\""
   ]
  },
  {
   "cell_type": "code",
   "execution_count": 6,
   "metadata": {},
   "outputs": [],
   "source": [
    "%load_ext autoreload\n",
    "%autoreload 2"
   ]
  },
  {
   "cell_type": "code",
   "execution_count": 7,
   "metadata": {},
   "outputs": [],
   "source": [
    "import torch\n",
    "import os\n",
    "import transformers\n",
    "import numpy as np\n",
    "import seaborn as sns\n",
    "import pandas as pd\n",
    "from transformers import file_utils\n",
    "from types import SimpleNamespace\n",
    "from datasets import Dataset\n",
    "import utils"
   ]
  },
  {
   "cell_type": "code",
   "execution_count": 8,
   "metadata": {},
   "outputs": [],
   "source": [
    "MODEL_FILE_NAME = 'pytorch_model.bin'\n",
    "model_dir = '..'\n",
    "batch_size = 64"
   ]
  },
  {
   "cell_type": "code",
   "execution_count": 9,
   "metadata": {},
   "outputs": [
    {
     "name": "stderr",
     "output_type": "stream",
     "text": [
      "Some weights of the model checkpoint at distilroberta-base were not used when initializing RobertaModel: ['lm_head.dense.bias', 'lm_head.decoder.weight', 'lm_head.layer_norm.weight', 'lm_head.layer_norm.bias', 'lm_head.dense.weight', 'lm_head.bias']\n",
      "- This IS expected if you are initializing RobertaModel from the checkpoint of a model trained on another task or with another architecture (e.g. initializing a BertForSequenceClassification model from a BertForPreTraining model).\n",
      "- This IS NOT expected if you are initializing RobertaModel from the checkpoint of a model that you expect to be exactly identical (initializing a BertForSequenceClassification model from a BertForSequenceClassification model).\n"
     ]
    }
   ],
   "source": [
    "model = utils.get_default_model()"
   ]
  },
  {
   "cell_type": "code",
   "execution_count": 10,
   "metadata": {},
   "outputs": [],
   "source": [
    "device = torch.device(\"cuda\" if torch.cuda.is_available() else \"cpu\")\n",
    "state_file = os.path.join(model_dir, MODEL_FILE_NAME)\n",
    "state_dict = torch.load(state_file, map_location=device)\n",
    "model.load_state_dict(state_dict)\n",
    "model = model.to(device)"
   ]
  },
  {
   "cell_type": "code",
   "execution_count": 11,
   "metadata": {},
   "outputs": [],
   "source": [
    "tokenizer = model.tokenizer\n",
    "pt_tensor_type = transformers.file_utils.TensorType.PYTORCH"
   ]
  },
  {
   "cell_type": "code",
   "execution_count": 12,
   "metadata": {},
   "outputs": [],
   "source": [
    "df = pd.read_csv('../test.csv')\n",
    "df = utils.preprocess_df(df)"
   ]
  },
  {
   "cell_type": "code",
   "execution_count": null,
   "metadata": {},
   "outputs": [
    {
     "name": "stdout",
     "output_type": "stream",
     "text": [
      "batch #1\n",
      "[2021-09-08 20:04:21.731 pytorch-1-6-cpu-py36--ml-t3-medium-370ee60fbc7a856e8f67ac271515:432 INFO utils.py:27] RULE_JOB_STOP_SIGNAL_FILENAME: None\n",
      "[2021-09-08 20:04:22.066 pytorch-1-6-cpu-py36--ml-t3-medium-370ee60fbc7a856e8f67ac271515:432 INFO profiler_config_parser.py:102] Unable to find config at /opt/ml/input/config/profilerconfig.json. Profiler is disabled.\n"
     ]
    }
   ],
   "source": [
    "prob_list = []\n",
    "model.eval()\n",
    "with torch.no_grad():\n",
    "    for i in range(0, len(df), batch_size):\n",
    "        print(f'batch #{i+1}')\n",
    "        batch_dict = {col: list(df.loc[i:i+batch_size, col]) for col in df.columns}\n",
    "        batch_input = utils.tokenize_fn(batch_dict, model.tokenizer, return_tensors=pt_tensor_type)\n",
    "        outputs = model(**batch_input)\n",
    "        probabilities = torch.nn.functional.softmax(outputs.logits, dim=1)\n",
    "        prob_list.append(probabilities)"
   ]
  },
  {
   "cell_type": "code",
   "execution_count": 1,
   "metadata": {},
   "outputs": [
    {
     "ename": "NameError",
     "evalue": "name 'prob_list' is not defined",
     "output_type": "error",
     "traceback": [
      "\u001b[0;31m---------------------------------------------------------------------------\u001b[0m",
      "\u001b[0;31mNameError\u001b[0m                                 Traceback (most recent call last)",
      "\u001b[0;32m<ipython-input-1-3d7893dad3c2>\u001b[0m in \u001b[0;36m<module>\u001b[0;34m\u001b[0m\n\u001b[0;32m----> 1\u001b[0;31m \u001b[0mprob_list\u001b[0m\u001b[0;34m\u001b[0m\u001b[0;34m\u001b[0m\u001b[0m\n\u001b[0m",
      "\u001b[0;31mNameError\u001b[0m: name 'prob_list' is not defined"
     ]
    }
   ],
   "source": [
    "prob_list"
   ]
  },
  {
   "cell_type": "code",
   "execution_count": 1,
   "metadata": {},
   "outputs": [
    {
     "ename": "NameError",
     "evalue": "name 'np' is not defined",
     "output_type": "error",
     "traceback": [
      "\u001b[0;31m---------------------------------------------------------------------------\u001b[0m",
      "\u001b[0;31mNameError\u001b[0m                                 Traceback (most recent call last)",
      "\u001b[0;32m<ipython-input-1-d794e6f1b65b>\u001b[0m in \u001b[0;36m<module>\u001b[0;34m\u001b[0m\n\u001b[0;32m----> 1\u001b[0;31m \u001b[0mprob_disaster\u001b[0m \u001b[0;34m=\u001b[0m \u001b[0mnp\u001b[0m\u001b[0;34m.\u001b[0m\u001b[0mvstack\u001b[0m\u001b[0;34m(\u001b[0m\u001b[0mprob_list\u001b[0m\u001b[0;34m)\u001b[0m\u001b[0;34m[\u001b[0m\u001b[0;34m:\u001b[0m\u001b[0;34m,\u001b[0m\u001b[0;36m1\u001b[0m\u001b[0;34m]\u001b[0m\u001b[0;34m\u001b[0m\u001b[0;34m\u001b[0m\u001b[0m\n\u001b[0m",
      "\u001b[0;31mNameError\u001b[0m: name 'np' is not defined"
     ]
    }
   ],
   "source": [
    "prob_disaster = np.vstack(prob_list)[:,1]"
   ]
  },
  {
   "cell_type": "code",
   "execution_count": 2,
   "metadata": {},
   "outputs": [
    {
     "ename": "NameError",
     "evalue": "name 'sns' is not defined",
     "output_type": "error",
     "traceback": [
      "\u001b[0;31m---------------------------------------------------------------------------\u001b[0m",
      "\u001b[0;31mNameError\u001b[0m                                 Traceback (most recent call last)",
      "\u001b[0;32m<ipython-input-2-5c1cfb152c0a>\u001b[0m in \u001b[0;36m<module>\u001b[0;34m\u001b[0m\n\u001b[0;32m----> 1\u001b[0;31m \u001b[0msns\u001b[0m\u001b[0;34m.\u001b[0m\u001b[0mhistplot\u001b[0m\u001b[0;34m(\u001b[0m\u001b[0mprob_disaster\u001b[0m\u001b[0;34m)\u001b[0m\u001b[0;34m\u001b[0m\u001b[0;34m\u001b[0m\u001b[0m\n\u001b[0m",
      "\u001b[0;31mNameError\u001b[0m: name 'sns' is not defined"
     ]
    }
   ],
   "source": [
    "sns.histplot(prob_disaster) "
   ]
  },
  {
   "cell_type": "code",
   "execution_count": 146,
   "metadata": {},
   "outputs": [
    {
     "data": {
      "text/plain": [
       "0.35243640821330063"
      ]
     },
     "execution_count": 146,
     "metadata": {},
     "output_type": "execute_result"
    }
   ],
   "source": [
    "np.sum(prob_disaster>0.5)/len(prob_disaster)"
   ]
  },
  {
   "cell_type": "code",
   "execution_count": 150,
   "metadata": {},
   "outputs": [],
   "source": [
    "df['target'] = [int(x) for x in prob_disaster>0.5]"
   ]
  },
  {
   "cell_type": "code",
   "execution_count": 151,
   "metadata": {},
   "outputs": [],
   "source": [
    "df_submission = df.loc[:,['id','target']]"
   ]
  },
  {
   "cell_type": "code",
   "execution_count": 153,
   "metadata": {},
   "outputs": [],
   "source": [
    "df_submission.to_csv('submission.csv',index=False)"
   ]
  },
  {
   "cell_type": "markdown",
   "metadata": {},
   "source": [
    "### Predict top 50% "
   ]
  },
  {
   "cell_type": "code",
   "execution_count": null,
   "metadata": {},
   "outputs": [],
   "source": []
  }
 ],
 "metadata": {
  "instance_type": "ml.t3.medium",
  "kernelspec": {
   "display_name": "Python 3 (PyTorch 1.6 Python 3.6 CPU Optimized)",
   "language": "python",
   "name": "python3__SAGEMAKER_INTERNAL__arn:aws:sagemaker:us-east-1:081325390199:image/pytorch-1.6-cpu-py36-ubuntu16.04-v1"
  },
  "language_info": {
   "codemirror_mode": {
    "name": "ipython",
    "version": 3
   },
   "file_extension": ".py",
   "mimetype": "text/x-python",
   "name": "python",
   "nbconvert_exporter": "python",
   "pygments_lexer": "ipython3",
   "version": "3.6.13"
  }
 },
 "nbformat": 4,
 "nbformat_minor": 4
}
